<?xml version="1.0" ?>
<!-- =================================================================================== -->
<!-- |    This document was autogenerated by xacro from /home/will/Sycobot/rubyrhod_ws/src/doosan-robot/dsr_description/xacro/m1013.urdf.xacro | -->
<!-- |    EDITING THIS FILE BY HAND IS NOT RECOMMENDED                                 | -->
<!-- =================================================================================== -->
<robot name="m1013">
    <material name="black">
        <color rgba="0.0 0.0 0.0 1.0" />
    </material>
    <material name="white">
        <color rgba="1.0 1.0 1.0 1.0" />
    </material>
    <material name="orange">
        <color rgba="1.0 0.4 0.0 1.0" />
    </material>
    <material name="dr_gray">
        <color rgba="0.490 0.490 0.486 1.0" />
    </material>
    <material name="dr_white">
        <color rgba="0.941 0.941 0.941 1.0" />
    </material>
    <link name="base_0">
        <inertial>
            <mass value="4.12" />
            <origin xyz="-3.4e-05   -0.004815    0.048482" />
            <inertia ixx="0.016331" ixy="-6.4837e-06" ixz="2.0048e-06" iyy="0.014945" iyz="-0.00051686" izz="0.022577" />
        </inertial>
        <visual>
            <origin rpy="0 0 0" xyz="0 0 0" />
            <geometry>
                <mesh filename="package://dsr_description/meshes/m1013_white/MF1013_0_0.dae" scale="0.001 0.001 0.001" />
            </geometry>
        </visual>
    </link>
    <!-- joint 1 -->
    <joint name="joint1" type="revolute">
        <parent link="base_0" />
        <child link="link1" />
        <origin rpy="0 0 0" xyz="0 0 0.1525" />
        <axis xyz="0 0 1" />
        <limit effort="346" lower="-1.5708" upper="1.5708" velocity="2.0944" />
        <dynamics friction="0" />
    </joint>
    <link name="link1">
        <inertial>
            <mass value="7.8" />
            <origin xyz="0.000119      0.0428   -0.006383" rpy="0 0 0" />
            <inertia ixx="0.04506" ixy="4.1126e-05" ixz="-5.2533e-05" iyy="0.029679" iyz="-0.0019959" izz="0.047056" />
        </inertial>
        <collision>
            <geometry>
                <cylinder length="0.2" radius="0.1" />
            </geometry>
        </collision>
        <visual>
            <origin rpy="0 0 0" xyz="0 0 0" />
            <geometry>
                <mesh filename="package://dsr_description/meshes/m1013_white/MF1013_1_0.dae" scale="0.001 0.001 0.001" />
            </geometry>
        </visual>
    </link>
    <!-- joint2 -->
    <joint name="joint2" type="revolute">
        <parent link="link1" />
        <child link="link2" />
        <origin rpy="0 -1.571 -1.571" xyz="0 0.0345 0" />
        <axis xyz="0 0 1" />
        <limit effort="346" lower="-3.1415" upper="3.1415" velocity="2.0944" />
        <dynamics friction="0" />
    </joint>
    <link name="link2">
        <inertial>
            <mass value="10.83" />
            <origin xyz="0.25973    -5.3e-05     0.15782" rpy="0 0 0" />
            <inertia ixx="0.037586" ixy="-0.00036999" ixz="-0.0069927" iyy="0.84943" iyz="4.0201e-05" izz="0.85021" />
        </inertial>
        <collision>
            <origin rpy="0 -1.571 0" xyz="0.3 0 0.1525" />
            <geometry>
                <cylinder length="0.75" radius="0.08" />
            </geometry>
        </collision>
        <visual>
            <origin rpy="0 0 0" xyz="0 0 0" />
            <geometry>
                <mesh filename="package://dsr_description/meshes/m1013_white/MF1013_2_0.dae" scale="0.001 0.001 0.001" />
            </geometry>
        </visual>
        <visual>
            <origin rpy="0 0 0" xyz="0 0 0" />
            <geometry>
                <mesh filename="package://dsr_description/meshes/m1013_white/MF1013_2_1.dae" scale="0.001 0.001 0.001" />
            </geometry>
        </visual>
        <visual>
            <origin rpy="0 0 0" xyz="0 0 0" />
            <geometry>
                <mesh filename="package://dsr_description/meshes/m1013_white/MF1013_2_2.dae" scale="0.001 0.001 0.001" />
            </geometry>
        </visual>
    </link>
    <!-- joint3 -->
    <joint name="joint3" type="revolute">
        <parent link="link2" />
        <child link="link3" />
        <origin rpy="0 0 1.571" xyz="0.62 0 0" />
        <axis xyz="0 0 1" />
        <limit effort="163" lower="-2.7925" upper="2.7925" velocity="3.1416" />
        <dynamics friction="0" />
    </joint>
    <link name="link3">
        <inertial>
            <mass value="3.68" />
            <origin xyz="-1.5e-05   -0.006702    0.044608" />
            <inertia ixx="0.018748" ixy="7.8071e-06" ixz="-5.0324e-06" iyy="0.018972" iyz="-0.00099342" izz="0.011502" />
        </inertial>
        <visual>
            <origin rpy="0 0 0" xyz="0 0 0" />
            <geometry>
                <mesh filename="package://dsr_description/meshes/m1013_white/MF1013_3_0.dae" scale="0.001 0.001 0.001" />
            </geometry>
        </visual>
    </link>
    <!-- joint4 -->
    <joint name="joint4" type="revolute">
        <parent link="link3" />
        <child link="link4" />
        <origin rpy="1.571 0 0" xyz="0 -0.559 0" />
        <axis xyz="0 0 1" />
        <limit effort="50" lower="-3.1415" upper="3.1415" velocity="3.927" />
        <dynamics friction="0" />
    </joint>
    <link name="link4">
        <inertial>
            <mass value="3.82" />
            <origin xyz="7.1e-05    0.091879    -0.18252" rpy="0 0 0" />
            <inertia ixx="0.19063" ixy="-1.8037e-05" ixz="-3.8576e-05" iyy="0.17268" iyz="-0.052996" izz="0.030386" />
        </inertial>
        <collision>
            <origin rpy="-0.55 0 0" xyz="0 0.07 -0.3" />
            <geometry>
                <cylinder length="0.4" radius="0.07" />
            </geometry>
        </collision>
        <visual>
            <origin rpy="0 0 0" xyz="0 0 0" />
            <geometry>
                <mesh filename="package://dsr_description/meshes/m1013_white/MF1013_4_0.dae" scale="0.001 0.001 0.001" />
            </geometry>
        </visual>
        <visual>
            <origin rpy="0 0 0" xyz="0 0 0" />
            <geometry>
                <mesh filename="package://dsr_description/meshes/m1013_white/MF1013_4_1.dae" scale="0.001 0.001 0.001" />
            </geometry>
        </visual>
    </link>
    <!-- joint5 -->
    <joint name="joint5" type="revolute">
        <parent link="link4" />
        <child link="link5" />
        <origin rpy="-1.571 0 0" xyz="0 0 0" />
        <axis xyz="0 0 1" />
        <limit effort="50" lower="-1.58825" upper="1.91986" velocity="3.927" />
        <dynamics friction="0" />
    </joint>
    <link name="link5">
        <inertial>
            <mass value="2.82" />
            <origin xyz="-0.000273    0.003651    0.032088" rpy="0 0 0" />
            <inertia ixx="0.015583" ixy="2.135e-05" ixz="-5.1895e-06" iyy="0.011519" iyz="0.00042553" izz="0.0088671" />
        </inertial>
        <collision>
            <origin rpy="1.571 0 0" xyz="0 0 0" />
            <geometry>
                <cylinder length="0.15" radius="0.08" />
            </geometry>
        </collision>
        <collision>
            <origin rpy="0 0 0" xyz="0 0 0.15" />
            <geometry>
                <cylinder length="0.15" radius="0.08" />
            </geometry>
        </collision>
        <visual>
            <origin rpy="0 0 0" xyz="0 0 0" />
            <geometry>
                <mesh filename="package://dsr_description/meshes/m1013_white/MF1013_5_0.dae" scale="0.001 0.001 0.001" />
            </geometry>
        </visual>
    </link>
    <!-- joint6 -->
    <joint name="joint6" type="revolute">
        <parent link="link5" />
        <child link="link6" />
        <origin rpy="1.571 0 0" xyz="0 -0.121 0" />
        <axis xyz="0 0 1" />
        <limit effort="50" lower="-2.61799" upper="0.872665" velocity="3.927" />
        <dynamics friction="0" />
    </joint>
    <link name="link6">
        <inertial>
            <mass value="1.16" />
            <origin xyz="-0.000292       7e-06     -0.0539" />
            <inertia ixx="0.0048282" ixy="4.1298e-06" ixz="6.9879e-06" iyy="0.0059519" iyz="4.252e-06" izz="0.0061263" />
        </inertial>
        <visual>
            <origin rpy="0 0 0" xyz="0 0 0" />
            <geometry>
                <mesh filename="package://dsr_description/meshes/m1013_white/MF1013_6_0.dae" scale="0.001 0.001 0.001" />
            </geometry>
        </visual>
    </link>
    <!-- Transmission 1 -->
    <transmission name="tran1">
        <type>transmission_interface/SimpleTransmission</type>
        <joint name="joint1">
            <hardwareInterface>hardware_interface/PositionJointInterface</hardwareInterface>
        </joint>
        <actuator name="motor1">
            <hardwareInterface>hardware_interface/PositionJointInterface</hardwareInterface>
            <mechanicalReduction>1</mechanicalReduction>
        </actuator>
    </transmission>
    <!-- Transmission 2 -->
    <transmission name="tran2">
        <type>transmission_interface/SimpleTransmission</type>
        <joint name="joint2">
            <hardwareInterface>hardware_interface/PositionJointInterface</hardwareInterface>
        </joint>
        <actuator name="motor2">
            <hardwareInterface>hardware_interface/PositionJointInterface</hardwareInterface>
            <mechanicalReduction>1</mechanicalReduction>
        </actuator>
    </transmission>
    <!-- Transmission 3 -->
    <transmission name="tran3">
        <type>transmission_interface/SimpleTransmission</type>
        <joint name="joint3">
            <hardwareInterface>hardware_interface/PositionJointInterface</hardwareInterface>
        </joint>
        <actuator name="motor3">
            <hardwareInterface>hardware_interface/PositionJointInterface</hardwareInterface>
            <mechanicalReduction>1</mechanicalReduction>
        </actuator>
    </transmission>
    <!-- Transmission 4 -->
    <transmission name="tran4">
        <type>transmission_interface/SimpleTransmission</type>
        <joint name="joint4">
            <hardwareInterface>hardware_interface/PositionJointInterface</hardwareInterface>
        </joint>
        <actuator name="motor4">
            <hardwareInterface>hardware_interface/PositionJointInterface</hardwareInterface>
            <mechanicalReduction>1</mechanicalReduction>
        </actuator>
    </transmission>
    <!-- Transmission 5 -->
    <transmission name="tran5">
        <type>transmission_interface/SimpleTransmission</type>
        <joint name="joint5">
            <hardwareInterface>hardware_interface/PositionJointInterface</hardwareInterface>
        </joint>
        <actuator name="motor5">
            <hardwareInterface>hardware_interface/PositionJointInterface</hardwareInterface>
            <mechanicalReduction>1</mechanicalReduction>
        </actuator>
    </transmission>
    <!-- Transmission 6 -->
    <transmission name="tran6">
        <type>transmission_interface/SimpleTransmission</type>
        <joint name="joint6">
            <hardwareInterface>hardware_interface/PositionJointInterface</hardwareInterface>
        </joint>
        <actuator name="motor6">
            <hardwareInterface>hardware_interface/PositionJointInterface</hardwareInterface>
            <mechanicalReduction>1</mechanicalReduction>
        </actuator>
    </transmission>
    <!-- Base -->
    <selfCollide>true</selfCollide>
    <gazebo reference="dsr01">
        <selfCollide>true</selfCollide>
        <plugin name="gazebo_ros_control">
            <robotNamespace>/</robotNamespace>
        </plugin>
    </gazebo>
    <gazebo reference="base_0">
        <selfCollide>true</selfCollide>
        <kp>1000000.0</kp>
        <kd>100.0</kd>
        <mu1>30.0</mu1>
        <mu2>30.0</mu2>
        <maxVel>1.0</maxVel>
        <minDepth>0.001</minDepth>
    </gazebo>
    <!-- Link1 -->
    <gazebo reference="link1">
        <selfCollide>true</selfCollide>
        <kp>1000000.0</kp>
        <kd>100.0</kd>
        <mu1>30.0</mu1>
        <mu2>30.0</mu2>
        <maxVel>1.0</maxVel>
        <minDepth>0.001</minDepth>
    </gazebo>
    <!-- Link2 -->
    <gazebo reference="link2">
        <selfCollide>true</selfCollide>
        <kp>1000000.0</kp>
        <kd>100.0</kd>
        <mu1>30.0</mu1>
        <mu2>30.0</mu2>
        <maxVel>1.0</maxVel>
        <minDepth>0.001</minDepth>
    </gazebo>
    <!-- Link3 -->
    <gazebo reference="link3">
        <selfCollide>true</selfCollide>
        <kp>1000000.0</kp>
        <kd>100.0</kd>
        <mu1>30.0</mu1>
        <mu2>30.0</mu2>
        <maxVel>1.0</maxVel>
        <minDepth>0.001</minDepth>
    </gazebo>
    <!-- Link4 -->
    <gazebo reference="link4">
        <selfCollide>true</selfCollide>
        <kp>1000000.0</kp>
        <kd>100.0</kd>
        <mu1>30.0</mu1>
        <mu2>30.0</mu2>
        <maxVel>1.0</maxVel>
        <minDepth>0.001</minDepth>
    </gazebo>
    <!-- Link5 -->
    <gazebo reference="link5">
        <selfCollide>true</selfCollide>
        <kp>1000000.0</kp>
        <kd>100.0</kd>
        <mu1>30.0</mu1>
        <mu2>30.0</mu2>
        <maxVel>1.0</maxVel>
        <minDepth>0.001</minDepth>
    </gazebo>
    <!-- Link6 -->
    <gazebo reference="link6">
        <selfCollide>true</selfCollide>
        <kp>1000000.0</kp>
        <kd>100.0</kd>
        <mu1>30.0</mu1>
        <mu2>30.0</mu2>
        <maxVel>1.0</maxVel>
        <minDepth>0.001</minDepth>
    </gazebo>
    <!-- ros_control plugin -->
    <gazebo>
        <selfCollide>true</selfCollide>
        <plugin filename="libgazebo_ros_control.so" name="gazebo_ros_control">
            <robotNamespace>/dsr</robotNamespace>
            <controlPeriod>0.001</controlPeriod>
            <robotSimType>gazebo_ros_control/DefaultRobotHWSim</robotSimType>
            <legacyModeNS>true</legacyModeNS>
        </plugin>
    </gazebo>
    <link name="world" />
    <!-- <link name="tcp" /> -->
    <!-- <link name="map" /> -->
    <!-- World fixed joint-->
    <joint name="world_fixed" type="fixed">
        <origin rpy="0 0 0" xyz="0 0 0" />
        <parent link="world" />
        <child link="base_0" />
    </joint>
    <!-- World fixed joint-->
    <!-- <joint name="map_planar" type="planar">
      <origin xyz="0 0 0" rpy="0 0 0"/>
      <parent link="map"/>
      <child link="world"/>
    </joint> -->
    <!-- TCP fixed joint-->
    <!-- <joint name="tcp_fixed" type="fixed">
    <origin xyz="0 0 0.1" rpy="0 -1.57075 0"/>
    <parent link="link6"/>
    <child link="tcp"/>
  </joint> -->
    <!-- <material name="black">
    <color rgba="0. 0. 0. 1" />
  </material>
  <material name="dark_grey">
    <color rgba="0.1 0.1 0.1 1" />
  </material>
  <material name="grey">
    <color rgba="0.6 0.6 0.6 1" />
  </material>
  <material name="white">
    <color rgba="0.9 0.9 0.9 1" />
  </material> -->
    <link name="camera_body">
        <visual>
            <origin xyz="0. 0. 0." />
            <geometry>
                <box size="0.0994 0.0996 0.023" />
            </geometry>
            <material name="white" />
        </visual>
        <collision>
            <geometry>
                <box size="0.1491 0.1494 0.0345" />
            </geometry>
        </collision>
        <inertial>
            <mass value="0.1" />
            <origin xyz="0 0 0" rpy="0 0 0" />
            <inertia ixx="0.03" iyy="0.03" izz="0.03" ixy="0.0" ixz="0.0" iyz="0.0" />
        </inertial>
    </link>
    <link name="camera_base">
        <visual>
            <origin xyz="-0.013 0. 0." />
            <geometry>
                <box size="0.026 0.103 0.039" />
            </geometry>
            <material name="grey" />
        </visual>
        <collision>
            <geometry>
                <box size="0.039 0.1545 0.0585" />
            </geometry>
        </collision>
        <inertial>
            <mass value="0.1" />
            <origin xyz="0 0 0" rpy="0 0 0" />
            <inertia ixx="0.03" iyy="0.03" izz="0.03" ixy="0.0" ixz="0.0" iyz="0.0" />
        </inertial>
    </link>
    <link name="camera_visor">
        <visual>
            <origin xyz="-0.0128 0. 0." />
            <geometry>
                <box size="0.026 0.101 0.037" />
            </geometry>
            <material name="black" />
        </visual>
        <collision>
            <geometry>
                <box size="0.039 0.1515 0.0555" />
            </geometry>
        </collision>
        <inertial>
            <mass value="0.1" />
            <origin xyz="0 0 0" rpy="0 0 0" />
            <inertia ixx="0.03" iyy="0.03" izz="0.03" ixy="0.0" ixz="0.0" iyz="0.0" />
        </inertial>
    </link>
    <link name="camera_depth" />
    <joint name="camera_base_to_body" type="fixed">
        <parent link="camera_base" />
        <child link="camera_body" />
        <origin rpy="0. 0. 0." xyz="-0.0757 0. 0.008" />
    </joint>
    <joint name="camera_base_to_visor" type="fixed">
        <parent link="camera_base" />
        <child link="camera_visor" />
        <origin rpy="0. 0. 0." xyz="0. 0. 0." />
    </joint>
    <joint name="camera_base_to_depth" type="fixed">
        <parent link="camera_base" />
        <child link="camera_depth" />
        <origin rpy="-1.57 0 -1.57" xyz="0 0 0 " />
    </joint>
    <!-- camera -->
    <gazebo reference="camera_base">
        <sensor name="camera" type="camera">
            <update_rate>30.0</update_rate>
            <camera name="head">
                <horizontal_fov>1.3962634</horizontal_fov>
                <image>
                    <width>800</width>
                    <height>800</height>
                    <format>R8G8B8</format>
                </image>
                <clip>
                    <near>0.002</near>
                    <far>300</far>
                </clip>
                <noise>
                    <type>gaussian</type>
                    <!-- Noise is sampled independently per pixel on each frame.
               That pixel's noise value is added to each of its color
               channels, which at that point lie in the range [0,1]. -->
                    <mean>0.0</mean>
                    <stddev>0.007</stddev>
                </noise>
            </camera>
            <plugin filename="libgazebo_ros_camera.so" name="camera_controller">
                <alwaysOn>true</alwaysOn>
                <updateRate>0.0</updateRate>
                <cameraName>/camera</cameraName>
                <imageTopicName>image_raw</imageTopicName>
                <cameraInfoTopicName>camera_info</cameraInfoTopicName>
                <frameName>camera_base</frameName>
                <hackBaseline>0.07</hackBaseline>
                <distortionK1>0.0</distortionK1>
                <distortionK2>0.0</distortionK2>
                <distortionK3>0.0</distortionK3>
                <distortionT1>0.0</distortionT1>
                <distortionT2>0.0</distortionT2>
            </plugin>
        </sensor>
    </gazebo>
    <gazebo reference="camera_base">
        <sensor name="camera_depth" type="depth">
            <update_rate>20</update_rate>
            <camera>
                <horizontal_fov>1.5</horizontal_fov>
                <image>
                    <width>640</width>
                    <height>576</height>
                    <format>L16</format>
                </image>
                <clip>
                    <near>0.0002</near>
                    <far>5</far>
                </clip>
            </camera>
            <plugin filename="libgazebo_ros_openni_kinect.so" name="depth_controller">
                <baseline>0.2</baseline>
                <alwaysOn>true</alwaysOn>
                <updateRate>1.0</updateRate>
                <cameraName>camera_ir</cameraName>
                <!-- <imageTopicName>/camera/depth/image_raw</imageTopicName> -->
                <!-- <cameraInfoTopicName>/camera/depth/camera_info</cameraInfoTopicName> -->
                <depthImageTopicName>/camera/depth/image_raw</depthImageTopicName>
                <depthImageInfoTopicName>/camera/depth/camera_info</depthImageInfoTopicName>
                <pointCloudTopicName>/camera/depth/points</pointCloudTopicName>
                <frameName>camera_depth</frameName>
                <pointCloudCutoff>0.5</pointCloudCutoff>
                <pointCloudCutoffMax>3.0</pointCloudCutoffMax>
                <distortionK1>0.00000001</distortionK1>
                <distortionK2>0.00000001</distortionK2>
                <distortionK3>0.00000001</distortionK3>
                <distortionT1>0.00000001</distortionT1>
                <distortionT2>0.00000001</distortionT2>
                <CxPrime>0</CxPrime>
                <Cx>0</Cx>
                <Cy>0</Cy>
                <focalLength>0</focalLength>
                <hackBaseline>0</hackBaseline>
            </plugin>
        </sensor>
    </gazebo>
    <joint name="camera_fixed" type="fixed">
        <origin rpy="0 -1.57 0" xyz="-0.08 -0.01 0.1" />
        <parent link="link6" />
        <child link="camera_base" />
    </joint>
    <link name="vacuum_base_link">
        <inertial>
            <origin rpy="0 0 0" xyz="6.517E-09 -0.014367 0.027764" />
            <mass value="0.097429" />
            <inertia ixx="0.00011904" ixy="-3.2786E-12" ixz="-1.6419E-11" iyy="0.000148" iyz="1.9632E-05" izz="0.00010905" />
        </inertial>
        <visual>
            <origin rpy="0 0 0" xyz="-0.035 -0.02 -0.035" />
            <geometry>
                <mesh filename="package://vacuum/meshes/tool.STL" scale="0.001 0.001 0.001" />
            </geometry>
            ;
            <material name="">
                <color rgba="0.96078 0.96078 0.96471 1" />
            </material>
        </visual>
        <!--    <collision>-->
        <!--      <origin-->
        <!--        xyz="-0.035 -0.02 -0.035"-->
        <!--        rpy="0 0 0" />-->
        <!--      <geometry>-->
        <!--        <mesh-->
        <!--          filename="package://vacuum/meshes/tool.STL" scale="0.0013 0.0013 0.0013"/>-->
        <!--      </geometry>-->
        <!--    </collision>-->
        <collision>
            <origin rpy="0 0 0" xyz="0.05 0 0" />
            <geometry>
                <box size="0.18 0.15 0.15" />
            </geometry>
        </collision>
    </link>
    <link name="vacuum_tube">
        <visual>
            <origin rpy="1.57 0 0" xyz=" 0 0.064 0" />
            <geometry>
                <cylinder length="0.128" radius="0.012" />
            </geometry>
            <material name="">
                <color rgba="0.96078 0.96078 0.96471 1" />
            </material>
        </visual>
        <collision>
            <origin rpy="1.57 0 0" xyz="0 0.064 0" />
            <geometry>
                <cylinder length="0.128" radius="0.012" />
            </geometry>
        </collision>
        <inertial>
            <mass value="0.1" />
            <origin xyz="0 0 0" rpy="0 0 0" />
            <inertia ixx="0.03" iyy="0.03" izz="0.03" ixy="0.0" ixz="0.0" iyz="0.0" />
        </inertial>
    </link>
    <link name="vacuum_sphere">
        <visual>
            <origin rpy="0 0 0" xyz=" 0 0.02 0" />
            <geometry>
                <sphere radius="0.015" />
            </geometry>
            <material name="">
                <color rgba="0.96078 0.96078 0.96471 1" />
            </material>
        </visual>
        <collision>
            <origin rpy="0 0 0" xyz="0 0.02 0" />
            <geometry>
                <sphere radius="0.020" />
            </geometry>
        </collision>
        <inertial>
            <mass value="0.1" />
            <origin xyz="0 0 0" rpy="0 0 0" />
            <inertia ixx="0.03" iyy="0.03" izz="0.03" ixy="0.0" ixz="0.0" iyz="0.0" />
        </inertial>
    </link>
    <link name="vacuum_tcp" />
    <link name="vacuum_safe_tcp" />
    <joint name="tube_joint" type="fixed">
        <origin rpy="0 0 0" xyz="0 0.13 0" />
        <parent link="vacuum_base_link" />
        <child link="vacuum_tube" />
    </joint>
    <joint name="sphere_joint" type="fixed">
        <origin rpy="0 0 0" xyz="0 0.128 0" />
        <parent link="vacuum_tube" />
        <child link="vacuum_sphere" />
    </joint>
    <joint name="tcp_joint" type="fixed">
        <origin rpy="0 0 0" xyz="0 0.048 0" />
        <parent link="vacuum_sphere" />
        <child link="vacuum_tcp" />
    </joint>
    <joint name="tcp_safe_joint" type="fixed">
        <origin rpy="0 0 0" xyz="0 0.05 0" />
        <parent link="vacuum_tcp" />
        <child link="vacuum_safe_tcp" />
    </joint>
    <joint name="vacuum_fixed" type="fixed">
        <origin rpy="1.57 0 0" xyz="0 0 0" />
        <parent link="link6" />
        <child link="vacuum_base_link" />
    </joint>
</robot>

