<?xml version="1.0"  encoding="utf-8"?>
<!-- =================================================================================== -->
<!-- |    This document was autogenerated by xacro from robot.urdf.xacro               | -->
<!-- |    EDITING THIS FILE BY HAND IS NOT RECOMMENDED                                 | -->
<!-- =================================================================================== -->
<robot name="sycobot">
  <link name="base_footprint"/>
  <joint name="base_joint" type="fixed">
    <parent link="base_footprint"/>
    <child link="base_link"/>
    <origin rpy="0 0 0" xyz="0 0 0"/>
  </joint>
  <link name="base_link">
    <inertial>
      <mass value="58.0"/>
      <origin rpy="0 0 0" xyz="0.037646 0 0.20"/>
      <inertia ixx="2.0609325089599997" ixy="0.0" ixz="0.0" iyy="4.34999826" iyz="0.0" izz="5.54093111696"/>
    </inertial>
    <visual>
      <origin rpy="0 0 0" xyz="0.037646 0 0"/>
      <geometry>
        <mesh filename="/home/will/Sycobot/rubyrhod_ws/src/mir_robot/mir_description/meshes/visual/mir_100_base.stl"/>
      </geometry>
      <material name="white">
        <color rgba="1 1 1 1"/>
      </material>
    </visual>
    <collision>
      <origin rpy="0 0 0" xyz="0.037646 0 0"/>
      <geometry>
        <mesh filename="/home/will/Sycobot/rubyrhod_ws/src/mir_robot/mir_description/meshes/collision/mir_100_base.stl"/>
      </geometry>
    </collision>
  </link>

  <!-- IMU -->
  <joint name="base_link_to_imu_joint" type="fixed">
    <parent link="base_link"/>
    <child link="imu_link"/>
    <origin rpy="0 0 0" xyz="0.0 0.0 0.25"/>
    <!-- same as real MiR -->
  </joint>
  <link name="imu_link"/>

  <!-- Create an alias for imu_link. This is necessary because the real MiR's
         TF has imu_link, but the imu_data topic is published in the imu_frame
         frame. -->
  <joint name="imu_link_to_imu_frame_joint" type="fixed">
    <parent link="imu_link"/>
    <child link="imu_frame"/>
    <origin rpy="0 0 0" xyz="0 0 0"/>
  </joint>
  <link name="imu_frame"/>
  <!-- Laser scanners -->
  <joint name="base_link_to_front_laser_joint" type="fixed">
    <parent link="base_link"/>
    <child link="front_laser_link"/>
    <origin rpy="0.0 0.0 0.7853981633974483" xyz="0.4288 0.2358 0.1914"/>
    <!-- from visually matching up the meshes of the MiR and the laser scanner -->
  </joint>
  <link name="front_laser_link">
    <visual>
      <origin rpy="3.141592653589793 0 0" xyz="0.0 0.0 0.0"/>
      <geometry>
        <mesh filename="/home/will/Sycobot/rubyrhod_ws/src/mir_robot/mir_description/meshes/visual/sick_lms-100.stl"/>
      </geometry>
      <!-- <xacro:insert_block name="material_yellow" /> -->
      <material name="black">
        <color rgba="0.1 0.1 0.1 1"/>
      </material>
    </visual>
    <collision>
      <origin rpy="3.141592653589793 0 0" xyz="0.0 0.0 0.0"/>
      <geometry>
        <mesh filename="/home/will/Sycobot/rubyrhod_ws/src/mir_robot/mir_description/meshes/visual/sick_lms-100.stl"/>
      </geometry>
    </collision>
    <inertial>
      <mass value="2.0"/>
      <origin xyz="0 0 0"/>
      <inertia ixx="0.009708329449999999" ixy="0.0" ixz="0.0" iyy="0.0097601627626" iyz="0.0" izz="0.0080601634426"/>
    </inertial>
  </link>

  <joint name="base_link_to_back_laser_joint" type="fixed">
    <parent link="base_link"/>
    <child link="back_laser_link"/>
    <origin rpy="0.0 0.0 -2.356194490192345" xyz="-0.3548 -0.2352 0.1914"/>
    <!-- from visually matching up the meshes of the MiR and the laser scanner -->
  </joint>
  <link name="back_laser_link">
    <visual>
      <origin rpy="3.141592653589793 0 0" xyz="0.0 0.0 0.0"/>
      <geometry>
        <mesh filename="/home/will/Sycobot/rubyrhod_ws/src/mir_robot/mir_description/meshes/visual/sick_lms-100.stl"/>
      </geometry>
      
      <material name="black">
        <color rgba="0.1 0.1 0.1 1"/>
      </material>
    </visual>
    <collision>
      <origin rpy="3.141592653589793 0 0" xyz="0.0 0.0 0.0"/>
      <geometry>
        <mesh filename="/home/will/Sycobot/rubyrhod_ws/src/mir_robot/mir_description/meshes/visual/sick_lms-100.stl"/>
      </geometry>
    </collision>
    <inertial>
      <mass value="2.0"/>
      <origin xyz="0 0 0"/>
      <inertia ixx="0.009708329449999999" ixy="0.0" ixz="0.0" iyy="0.0097601627626" iyz="0.0" izz="0.0080601634426"/>
    </inertial>
  </link>

  <!-- Ultrasound sensors -->
  <joint name="us_1_joint" type="fixed">
    <!-- right ultrasound -->
    <parent link="base_link"/>
    <child link="us_1_frame"/>
    <origin rpy="0 0 0" xyz="0.45 -0.12 0.16 "/>
    <!-- from visually matching to the mesh of the MiR -->
  </joint>
  <link name="us_1_frame"/>
  <joint name="us_2_joint" type="fixed">
    <!-- left ultrasound -->
    <parent link="base_link"/>
    <child link="us_2_frame"/>
    <origin rpy="0 0 0" xyz="0.45 0.12 0.16 "/>
    <!-- from visually matching to the mesh of the MiR -->
  </joint>
  <link name="us_2_frame"/>
  <joint name="left_wheel_joint" type="continuous">
    <origin rpy="0 0 0" xyz="0.0 0.222604 0.0625"/>
    <parent link="base_link"/>
    <child link="left_wheel_link"/>
    <axis xyz="0 1 0"/>
    <limit effort="100" velocity="20.0"/>
  </joint>
  <link name="left_wheel_link">
    <inertial>
      <mass value="1.0"/>
      <origin rpy="1.5707963267948966 0 0" xyz="0 0 0"/>
      <inertia ixx="0.001061895408575" ixy="0.0" ixz="0.0" iyy="0.001061895408575" iyz="0.0" izz="0.001953125"/>
    </inertial>
    <visual>
      <origin rpy="0 0 0" xyz="0 0 0"/>
      <geometry>
        <mesh filename="/home/will/Sycobot/rubyrhod_ws/src/mir_robot/mir_description/meshes/visual/wheel.stl"/>
      </geometry>
      <material name="dark_grey">
        <color rgba="0.3 0.3 0.3 1"/>
      </material>
    </visual>
    <collision>
      <origin rpy="1.5707963267948966 0 0" xyz="0 0 0"/>
      <geometry>
        <cylinder length="0.032" radius="0.0625"/>
      </geometry>
    </collision>
  </link>
 
  <joint name="right_wheel_joint" type="continuous">
    <origin rpy="0 0 0" xyz="0.0 -0.222604 0.0625"/>
    <parent link="base_link"/>
    <child link="right_wheel_link"/>
    <axis xyz="0 1 0"/>
    <limit effort="100" velocity="20.0"/>
  </joint>
  <link name="right_wheel_link">
    <inertial>
      <mass value="1.0"/>
      <origin rpy="1.5707963267948966 0 0" xyz="0 0 0"/>
      <inertia ixx="0.001061895408575" ixy="0.0" ixz="0.0" iyy="0.001061895408575" iyz="0.0" izz="0.001953125"/>
    </inertial>
    <visual>
      <origin rpy="0 0 0" xyz="0 0 0"/>
      <geometry>
        <mesh filename="/home/will/Sycobot/rubyrhod_ws/src/mir_robot/mir_description/meshes/visual/wheel.stl"/>
      </geometry>
      <material name="dark_grey">
        <color rgba="0.3 0.3 0.3 1"/>
      </material>
    </visual>
    <collision>
      <origin rpy="1.5707963267948966 0 0" xyz="0 0 0"/>
      <geometry>
        <cylinder length="0.032" radius="0.0625"/>
      </geometry>
    </collision>
  </link>

  <!-- caster hub -->
  <joint name="fl_caster_rotation_joint" type="continuous">
    <origin rpy="0 0 0" xyz="0.341346 0.203 0.1565"/>
    <parent link="base_link"/>
    <child link="fl_caster_rotation_link"/>
    <axis xyz="0 0 1"/>
    <dynamics damping="0.01" friction="0.0"/>
  </joint>
  <link name="fl_caster_rotation_link">
    <inertial>
     
      <origin rpy="0.41887903200000004 0 1.5707963267948966 " xyz="0 0 -0.042500000044"/>
      <mass value="0.3097539019"/>
      <inertia ixx="0.0005844517978" ixy="0" ixz="0" iyy="0.00052872551237" iyz="0" izz="0.00017923555074"/>
    </inertial>
    <visual>
      <origin rpy="0 0 0" xyz="0 0 0"/>
      <geometry>
        <mesh filename="/home/will/Sycobot/rubyrhod_ws/src/mir_robot/mir_description/meshes/visual/caster_wheel_base.stl"/>
      </geometry>
      <material name="silver">
        <color rgba="0.79 0.82 0.93 1"/>
      </material>
    </visual>
    <collision>
      <origin rpy="0 0 0" xyz="0 0 0"/>
      <geometry>
        <mesh filename="/home/will/Sycobot/rubyrhod_ws/src/mir_robot/mir_description/meshes/collision/caster_wheel_base.stl"/>
      </geometry>
    </collision>
  </link>

  <!-- caster wheel -->
  <joint name="fl_caster_wheel_joint" type="continuous">
    <origin rpy="0 0 0" xyz="-0.0382 0 -0.094"/>
    <parent link="fl_caster_rotation_link"/>
    <child link="fl_caster_wheel_link"/>
    <axis xyz="0 1 0"/>
  </joint>
  <link name="fl_caster_wheel_link">
    <inertial>
      <mass value="1.0"/>
      <origin rpy="1.5707963267948966 0 0" xyz="0 0 0"/>
      <inertia ixx="0.001061895408575" ixy="0.0" ixz="0.0" iyy="0.001061895408575" iyz="0.0" izz="0.001953125"/>
    </inertial>
    <visual>
      <origin rpy="0 0 0" xyz="0 0 0"/>
      <geometry>
        <mesh filename="/home/will/Sycobot/rubyrhod_ws/src/mir_robot/mir_description/meshes/visual/wheel.stl"/>
      </geometry>
      <material name="dark_grey">
        <color rgba="0.3 0.3 0.3 1"/>
      </material>
    </visual>
    <collision>
      <origin rpy="1.5707963267948966 0 0" xyz="0 0 0"/>
      <geometry>
        <cylinder length="0.032" radius="0.0625"/>
      </geometry>
    </collision>
  </link>

  <!-- caster hub -->
  <joint name="fr_caster_rotation_joint" type="continuous">
    <origin rpy="0 0 0" xyz="0.341346 -0.203 0.1565"/>
    <parent link="base_link"/>
    <child link="fr_caster_rotation_link"/>
    <axis xyz="0 0 1"/>
    <dynamics damping="0.01" friction="0.0"/>
  </joint>
  <link name="fr_caster_rotation_link">
    <inertial>
 
      <origin rpy="0.41887903200000004 0 1.5707963267948966 " xyz="0 0 -0.042500000044"/>
      <mass value="0.3097539019"/>
      <inertia ixx="0.0005844517978" ixy="0" ixz="0" iyy="0.00052872551237" iyz="0" izz="0.00017923555074"/>
    </inertial>
    <visual>
      <origin rpy="0 0 0" xyz="0 0 0"/>
      <geometry>
        <mesh filename="/home/will/Sycobot/rubyrhod_ws/src/mir_robot/mir_description/meshes/visual/caster_wheel_base.stl"/>
      </geometry>
      <material name="silver">
        <color rgba="0.79 0.82 0.93 1"/>
      </material>
    </visual>
    <collision>
      <origin rpy="0 0 0" xyz="0 0 0"/>
      <geometry>
        <mesh filename="/home/will/Sycobot/rubyrhod_ws/src/mir_robot/mir_description/meshes/collision/caster_wheel_base.stl"/>
      </geometry>
    </collision>
  </link>


  <joint name="fr_caster_wheel_joint" type="continuous">
    <origin rpy="0 0 0" xyz="-0.0382 0 -0.094"/>
    <parent link="fr_caster_rotation_link"/>
    <child link="fr_caster_wheel_link"/>
    <axis xyz="0 1 0"/>
  </joint>
  <link name="fr_caster_wheel_link">
    <inertial>
      <mass value="1.0"/>
      <origin rpy="1.5707963267948966 0 0" xyz="0 0 0"/>
      <inertia ixx="0.001061895408575" ixy="0.0" ixz="0.0" iyy="0.001061895408575" iyz="0.0" izz="0.001953125"/>
    </inertial>
    <visual>
      <origin rpy="0 0 0" xyz="0 0 0"/>
      <geometry>
        <mesh filename="/home/will/Sycobot/rubyrhod_ws/src/mir_robot/mir_description/meshes/visual/wheel.stl"/>
      </geometry>
      <material name="dark_grey">
        <color rgba="0.3 0.3 0.3 1"/>
      </material>
    </visual>
    <collision>
      <origin rpy="1.5707963267948966 0 0" xyz="0 0 0"/>
      <geometry>
        <cylinder length="0.032" radius="0.0625"/>
      </geometry>
    </collision>
  </link>


  <joint name="bl_caster_rotation_joint" type="continuous">
    <origin rpy="0 0 0" xyz="-0.270154 0.203 0.1565"/>
    <parent link="base_link"/>
    <child link="bl_caster_rotation_link"/>
    <axis xyz="0 0 1"/>
    <dynamics damping="0.01" friction="0.0"/>
  </joint>
  <link name="bl_caster_rotation_link">
    <inertial>
     
      <origin rpy="0.41887903200000004 0 1.5707963267948966 " xyz="0 0 -0.042500000044"/>
      <mass value="0.3097539019"/>
      <inertia ixx="0.0005844517978" ixy="0" ixz="0" iyy="0.00052872551237" iyz="0" izz="0.00017923555074"/>
    </inertial>
    <visual>
      <origin rpy="0 0 0" xyz="0 0 0"/>
      <geometry>
        <mesh filename="/home/will/Sycobot/rubyrhod_ws/src/mir_robot/mir_description/meshes/visual/caster_wheel_base.stl"/>
      </geometry>
      <material name="silver">
        <color rgba="0.79 0.82 0.93 1"/>
      </material>
    </visual>
    <collision>
      <origin rpy="0 0 0" xyz="0 0 0"/>
      <geometry>
        <mesh filename="/home/will/Sycobot/rubyrhod_ws/src/mir_robot/mir_description/meshes/collision/caster_wheel_base.stl"/>
      </geometry>
    </collision>
  </link>

  <!-- caster wheel -->
  <joint name="bl_caster_wheel_joint" type="continuous">
    <origin rpy="0 0 0" xyz="-0.0382 0 -0.094"/>
    <parent link="bl_caster_rotation_link"/>
    <child link="bl_caster_wheel_link"/>
    <axis xyz="0 1 0"/>
  </joint>
  <link name="bl_caster_wheel_link">
    <inertial>
      <mass value="1.0"/>
      <origin rpy="1.5707963267948966 0 0" xyz="0 0 0"/>
      <inertia ixx="0.001061895408575" ixy="0.0" ixz="0.0" iyy="0.001061895408575" iyz="0.0" izz="0.001953125"/>
    </inertial>
    <visual>
      <origin rpy="0 0 0" xyz="0 0 0"/>
      <geometry>
        <mesh filename="/home/will/Sycobot/rubyrhod_ws/src/mir_robot/mir_description/meshes/visual/wheel.stl"/>
      </geometry>
      <material name="dark_grey">
        <color rgba="0.3 0.3 0.3 1"/>
      </material>
    </visual>
    <collision>
      <origin rpy="1.5707963267948966 0 0" xyz="0 0 0"/>
      <geometry>
        <cylinder length="0.032" radius="0.0625"/>
      </geometry>
    </collision>
  </link>

  <!-- caster hub -->
  <joint name="br_caster_rotation_joint" type="continuous">
    <origin rpy="0 0 0" xyz="-0.270154 -0.203 0.1565"/>
    <parent link="base_link"/>
    <child link="br_caster_rotation_link"/>
    <axis xyz="0 0 1"/>
    <dynamics damping="0.01" friction="0.0"/>
  </joint>
  <link name="br_caster_rotation_link">
    <inertial>
      <!-- <origin xyz="0 0 -0.042500000044" rpy="${0.5 * pi} ${24 * deg_to_rad} ${1.5 * pi}" /> -->
      <origin rpy="0.41887903200000004 0 1.5707963267948966 " xyz="0 0 -0.042500000044"/>
      <mass value="0.3097539019"/>
      <inertia ixx="0.0005844517978" ixy="0" ixz="0" iyy="0.00052872551237" iyz="0" izz="0.00017923555074"/>
    </inertial>
    <visual>
      <origin rpy="0 0 0" xyz="0 0 0"/>
      <geometry>
        <mesh filename="/home/will/Sycobot/rubyrhod_ws/src/mir_robot/mir_description/meshes/visual/caster_wheel_base.stl"/>
      </geometry>
      <material name="silver">
        <color rgba="0.79 0.82 0.93 1"/>
      </material>
    </visual>
    <collision>
      <origin rpy="0 0 0" xyz="0 0 0"/>
      <geometry>
        <mesh filename="/home/will/Sycobot/rubyrhod_ws/src/mir_robot/mir_description/meshes/collision/caster_wheel_base.stl"/>
      </geometry>
    </collision>
  </link>

  <!-- caster wheel -->
  <joint name="br_caster_wheel_joint" type="continuous">
    <origin rpy="0 0 0" xyz="-0.0382 0 -0.094"/>
    <parent link="br_caster_rotation_link"/>
    <child link="br_caster_wheel_link"/>
    <axis xyz="0 1 0"/>
  </joint>
  <link name="br_caster_wheel_link">
    <inertial>
      <mass value="1.0"/>
      <origin rpy="1.5707963267948966 0 0" xyz="0 0 0"/>
      <inertia ixx="0.001061895408575" ixy="0.0" ixz="0.0" iyy="0.001061895408575" iyz="0.0" izz="0.001953125"/>
    </inertial>
    <visual>
      <origin rpy="0 0 0" xyz="0 0 0"/>
      <geometry>
        <mesh filename="/home/will/Sycobot/rubyrhod_ws/src/mir_robot/mir_description/meshes/visual/wheel.stl"/>
      </geometry>
      <material name="dark_grey">
        <color rgba="0.3 0.3 0.3 1"/>
      </material>
    </visual>
    <collision>
      <origin rpy="1.5707963267948966 0 0" xyz="0 0 0"/>
      <geometry>
        <cylinder length="0.032" radius="0.0625"/>
      </geometry>
    </collision>
  </link>

  <joint name="base_link_surface_joint" type="fixed">
    <origin rpy="0 0 0" xyz="0.037646 0 0.352"/>
    <parent link="base_link"/>
    <child link="surface"/>
    <axis xyz="0 0 1"/>
  </joint>
  <link name="surface"/>


  <!-- DOOSAN -->
  <!--  	 <xacro:include filename="$(find dsr_description)/config/macro.gazebo.xacro" />-->
  <!--	 <xacro:include filename="$(find dsr_description)/config/macro.transmission.xacro" />-->
  <!--	 <xacro:include filename="$(find dsr_description)/config/macro.materials.xacro" />-->
  <link name="base_0">
    <inertial>
      <mass value="4.12"/>
      <origin xyz="-3.4e-05   -0.004815    0.048482"/>
      <inertia ixx="0.016331" ixy="-6.4837e-06" ixz="2.0048e-06" iyy="0.014945" iyz="-0.00051686" izz="0.022577"/>
    </inertial>
    <visual>
      <origin rpy="0 0 0" xyz="0 0 0"/>
      <geometry>
        <mesh filename="/home/will/Sycobot/rubyrhod_ws/src/doosan-robot/dsr_description/meshes/m1013_white/MF1013_0_0.dae" scale="0.001 0.001 0.001"/>
      </geometry>
    </visual>
  </link>
  <!-- joint 1 -->
  <joint name="joint1" type="revolute">
    <parent link="base_0"/>
    <child link="link1"/>
    <origin rpy="0 0 0" xyz="0 0 0.1525"/>
    <axis xyz="0 0 1"/>
    <limit effort="346" lower="-1.5708" upper="0.785398" velocity="2.0944"/>
    <dynamics friction="0"/>
  </joint>
  <link name="link1">
    <inertial>
      <mass value="7.8"/>
      <origin xyz="0.000119      0.0428   -0.006383"/>
      <inertia ixx="0.04506" ixy="4.1126e-05" ixz="-5.2533e-05" iyy="0.029679" iyz="-0.0019959" izz="0.047056"/>
    </inertial>
    <collision>
      <geometry>
        <cylinder length="0.2" radius="0.1"/>
      </geometry>
    </collision>
    <visual>
      <origin rpy="0 0 0" xyz="0 0 0"/>
      <geometry>
        <mesh filename="/home/will/Sycobot/rubyrhod_ws/src/doosan-robot/dsr_description/meshes/m1013_white/MF1013_1_0.dae" scale="0.001 0.001 0.001"/>
      </geometry>
    </visual>
  </link>
  <!-- joint2 -->
  <joint name="joint2" type="revolute">
    <parent link="link1"/>
    <child link="link2"/>
    <origin rpy="0 -1.571 -1.571" xyz="0 0.0345 0"/>
    <axis xyz="0 0 1"/>
    <limit effort="346" lower="-6.2832" upper="6.2832" velocity="2.0944"/>
    <dynamics friction="0"/>
  </joint>
  <link name="link2">
    <inertial>
      <mass value="10.83"/>
      <origin xyz="0.25973    -5.3e-05     0.15782"/>
      <inertia ixx="0.037586" ixy="-0.00036999" ixz="-0.0069927" iyy="0.84943" iyz="4.0201e-05" izz="0.85021"/>
    </inertial>
    <collision>
      <origin rpy="0 -1.571 0" xyz="0.3 0 0.1525"/>
      <geometry>
        <cylinder length="0.75" radius="0.08"/>
      </geometry>
    </collision>
    <visual>
      <origin rpy="0 0 0" xyz="0 0 0"/>
      <geometry>
        <mesh filename="/home/will/Sycobot/rubyrhod_ws/src/doosan-robot/dsr_description/meshes/m1013_white/MF1013_2_0.dae" scale="0.001 0.001 0.001"/>
      </geometry>
    </visual>
    <visual>
      <origin rpy="0 0 0" xyz="0 0 0"/>
      <geometry>
        <mesh filename="/home/will/Sycobot/rubyrhod_ws/src/doosan-robot/dsr_description/meshes/m1013_white/MF1013_2_1.dae" scale="0.001 0.001 0.001"/>
      </geometry>
    </visual>
    <visual>
      <origin rpy="0 0 0" xyz="0 0 0"/>
      <geometry>
        <mesh filename="/home/will/Sycobot/rubyrhod_ws/src/doosan-robot/dsr_description/meshes/m1013_white/MF1013_2_2.dae" scale="0.001 0.001 0.001"/>
      </geometry>
    </visual>
  </link>
  <!-- joint3 -->
  <joint name="joint3" type="revolute">
    <parent link="link2"/>
    <child link="link3"/>
    <origin rpy="0 0 1.571" xyz="0.62 0 0"/>
    <axis xyz="0 0 1"/>
    <limit effort="163" lower="-2.7925" upper="2.7925" velocity="3.1416"/>
    <dynamics friction="0"/>
  </joint>
  <link name="link3">
    <inertial>
      <mass value="3.68"/>
      <origin xyz="-1.5e-05   -0.006702    0.044608"/>
      <inertia ixx="0.018748" ixy="7.8071e-06" ixz="-5.0324e-06" iyy="0.018972" iyz="-0.00099342" izz="0.011502"/>
    </inertial>
    <visual>
      <origin rpy="0 0 0" xyz="0 0 0"/>
      <geometry>
        <mesh filename="/home/will/Sycobot/rubyrhod_ws/src/doosan-robot/dsr_description/meshes/m1013_white/MF1013_3_0.dae" scale="0.001 0.001 0.001"/>
      </geometry>
    </visual>
  </link>
  <!-- joint4 -->
  <joint name="joint4" type="revolute">
    <parent link="link3"/>
    <child link="link4"/>
    <origin rpy="1.571 0 0" xyz="0 -0.559 0"/>
    <axis xyz="0 0 1"/>
    <limit effort="50" lower="0" upper="6.2832" velocity="3.927"/>
    <dynamics friction="0"/>
  </joint>
  <link name="link4">
    <inertial>
      <mass value="3.82"/>
      <origin xyz="7.1e-05    0.091879    -0.18252"/>
      <inertia ixx="0.19063" ixy="-1.8037e-05" ixz="-3.8576e-05" iyy="0.17268" iyz="-0.052996" izz="0.030386"/>
    </inertial>
    <collision>
      <origin rpy="-0.55 0 0" xyz="0 0.07 -0.3"/>
      <geometry>
        <cylinder length="0.4" radius="0.07"/>
      </geometry>
    </collision>
    <visual>
      <origin rpy="0 0 0" xyz="0 0 0"/>
      <geometry>
        <mesh filename="/home/will/Sycobot/rubyrhod_ws/src/doosan-robot/dsr_description/meshes/m1013_white/MF1013_4_0.dae" scale="0.001 0.001 0.001"/>
      </geometry>
    </visual>
    <visual>
      <origin rpy="0 0 0" xyz="0 0 0"/>
      <geometry>
        <mesh filename="/home/will/Sycobot/rubyrhod_ws/src/doosan-robot/dsr_description/meshes/m1013_white/MF1013_4_1.dae" scale="0.001 0.001 0.001"/>
      </geometry>
    </visual>
  </link>
  <!-- joint5 -->
  <joint name="joint5" type="revolute">
    <parent link="link4"/>
    <child link="link5"/>
    <origin rpy="-1.571 0 0" xyz="0 0 0"/>
    <axis xyz="0 0 1"/>
    <limit effort="50" lower="-1.74533" upper="1.57" velocity="3.927"/>
    <dynamics friction="0"/>
  </joint>
  <link name="link5">
    <inertial>
      <mass value="2.82"/>
      <origin xyz="-0.000273    0.003651    0.032088"/>
      <inertia ixx="0.015583" ixy="2.135e-05" ixz="-5.1895e-06" iyy="0.011519" iyz="0.00042553" izz="0.0088671"/>
    </inertial>
    <collision>
      <origin rpy="1.571 0 0" xyz="0 0 0"/>
      <geometry>
        <cylinder length="0.15" radius="0.08"/>
      </geometry>
    </collision>
    <collision>
      <origin rpy="0 0 0" xyz="0 0 0.15"/>
      <geometry>
        <cylinder length="0.15" radius="0.08"/>
      </geometry>
    </collision>
    <visual>
      <origin rpy="0 0 0" xyz="0 0 0"/>
      <geometry>
        <mesh filename="/home/will/Sycobot/rubyrhod_ws/src/doosan-robot/dsr_description/meshes/m1013_white/MF1013_5_0.dae" scale="0.001 0.001 0.001"/>
      </geometry>
    </visual>
  </link>
  <!-- joint6 -->
  <joint name="joint6" type="revolute">
    <parent link="link5"/>
    <child link="link6"/>
    <origin rpy="1.571 0 0" xyz="0 -0.121 0"/>
    <axis xyz="0 0 1"/>
    <limit effort="50" lower="-3.1415" upper="0" velocity="3.927"/>
    <dynamics friction="0"/>
  </joint>
  <link name="link6">
    <inertial>
      <mass value="1.16"/>
      <origin xyz="-0.000292       7e-06     -0.0539"/>
      <inertia ixx="0.0048282" ixy="4.1298e-06" ixz="6.9879e-06" iyy="0.0059519" iyz="4.252e-06" izz="0.0061263"/>
    </inertial>
    <visual>
      <origin rpy="0 0 0" xyz="0 0 0"/>
      <geometry>
        <mesh filename="/home/will/Sycobot/rubyrhod_ws/src/doosan-robot/dsr_description/meshes/m1013_white/MF1013_6_0.dae" scale="0.001 0.001 0.001"/>
      </geometry>
    </visual>
  </link>



  <link name="camera_body">
    <visual>
      <origin xyz="0. 0. 0."/>
      <geometry>
        <box size="0.0994 0.0996 0.023"/>
      </geometry>
      <material name="white"/>
    </visual>
    <collision>
      <geometry>
        <box size="0.0994 0.0996 0.023"/>
      </geometry>
    </collision>
  </link>
  <link name="camera_base">
    <visual>
      <origin xyz="-0.013 0. 0."/>
      <geometry>
        <box size="0.026 0.103 0.039"/>
      </geometry>
      <material name="grey"/>
    </visual>
    <collision>
      <geometry>
        <box size="0.026 0.103 0.039"/>
      </geometry>
    </collision>
  </link>
  <link name="camera_visor">
    <visual>
      <origin xyz="-0.0128 0. 0."/>
      <geometry>
        <box size="0.026 0.101 0.037"/>
      </geometry>
      <material name="black"/>
    </visual>
    <collision>
      <geometry>
        <box size="0.026 0.101 0.037"/>
      </geometry>
    </collision>
  </link>
  <link name="camera_depth"/>
  <joint name="camera_base_to_body" type="fixed">
    <parent link="camera_base"/>
    <child link="camera_body"/>
    <origin rpy="0. 0. 0." xyz="-0.0757 0. 0.008"/>
  </joint>
  <joint name="camera_base_to_visor" type="fixed">
    <parent link="camera_base"/>
    <child link="camera_visor"/>
    <origin rpy="0. 0. 0." xyz="0. 0. 0."/>
  </joint>
  <joint name="camera_base_to_depth" type="fixed">
    <parent link="camera_base"/>
    <child link="camera_depth"/>
    <origin rpy="-1.57 0 -1.57" xyz="0 0 0 "/>
  </joint>


  <joint name="camera_fixed" type="fixed">
    <origin rpy="0 -1.57 0" xyz="-0.05 0 0.1"/>
    <parent link="link6"/>
    <child link="camera_base"/>
  </joint>
  <link name="vacuum_base_link">
    <inertial>
      <origin rpy="0 0 0" xyz="6.517E-09 -0.014367 0.027764"/>
      <mass value="0.097429"/>
      <inertia ixx="0.00011904" ixy="-3.2786E-12" ixz="-1.6419E-11" iyy="0.000148" iyz="1.9632E-05" izz="0.00010905"/>
    </inertial>
    <visual>
      <origin rpy="0 0 0" xyz="-0.035 -0.02 -0.035"/>
      <geometry>
        <mesh filename="/home/will/Sycobot/rubyrhod_ws/src/vacuum/meshes/tool.STL" scale="0.001 0.001 0.001"/>
      </geometry>
      <material name="">
        <color rgba="0.96078 0.96078 0.96471 1"/>
      </material>
    </visual>
    <collision>
      <origin rpy="0 0 0" xyz="-0.035 -0.02 -0.035"/>
      <geometry>
        <mesh filename="/home/will/Sycobot/rubyrhod_ws/src/vacuum/meshes/tool.STL" scale="0.0010 0.0010 0.0010"/>
      </geometry>
    </collision>
  </link>
  <link name="vacuum_tube">
    <visual>
      <origin rpy="1.57 0 0" xyz=" 0 0.075 0"/>
      <geometry>
        <cylinder length="0.15" radius="0.015"/>
      </geometry>
      <material name="">
        <color rgba="0.96078 0.96078 0.96471 1"/>
      </material>
    </visual>
    <collision>
      <origin rpy="1.57 0 0" xyz="0 0.075 0"/>
      <geometry>
        <cylinder length="0.15" radius="0.02"/>
      </geometry>
    </collision>
  </link>
  <link name="vacuum_tcp">
  </link>
  <link name="vacuum_safe_tcp">
  </link>
  <joint name="tube_joint" type="fixed">
    <origin rpy="0 0 0" xyz="0 0.105 0"/>
    <parent link="vacuum_base_link"/>
    <child link="vacuum_tube"/>
  </joint>
  <joint name="tcp_joint" type="fixed">
    <origin rpy="0 0 0" xyz="0 0.15 0"/>
    <parent link="vacuum_tube"/>
    <child link="vacuum_tcp"/>
  </joint>
  <joint name="tcp_safe_joint" type="fixed">
    <origin rpy="0 0 0" xyz="0 0.05 0"/>
    <parent link="vacuum_tcp"/>
    <child link="vacuum_safe_tcp"/>
  </joint>
  <joint name="vacuum_fixed" type="fixed">
    <origin rpy="1.57 0 0" xyz="0 0 0"/>
    <parent link="link6"/>
    <child link="vacuum_base_link"/>
  </joint>
  
  <link name="structure_vention">
    <inertial>
      <origin rpy="0 0 0" xyz="0.68508 0.51499 -0.58331"/>
      <mass value="10.179"/>
      <inertia ixx="0.092649" ixy="1.2619E-05" ixz="-0.00019211" iyy="0.16229" iyz="-5.2257E-05" izz="0.088828"/>
    </inertial>
    <visual>
      <origin rpy="0 0 0" xyz="0 0 0"/>
      <geometry>
        <mesh filename="/home/will/Sycobot/rubyrhod_ws/src/vention/meshes/structure_vention.STL"/>
      </geometry>
      <material name="">
        <color rgba="0.33725 0.52941 0.75686 1"/>
      </material>
    </visual>
    <collision>
      <origin rpy="0 0 0" xyz="0 0 0"/>
      <geometry>
        <mesh filename="/home/will/Sycobot/rubyrhod_ws/src/vention/meshes/structure_vention.STL"/>
      </geometry>
    </collision>
  </link>
  <link name="plate_arm">
    <inertial>
      <origin rpy="0 0 0" xyz="1.9231E-09 0.0056003 3.6942E-09"/>
      <mass value="0.44151"/>
      <inertia ixx="0.0021724" ixy="7.5078E-13" ixz="-9.242E-07" iyy="0.0043355" iyz="1.3802E-12" izz="0.0021724"/>
    </inertial>
    <visual>
      <origin rpy="0 0 0" xyz="0 0 0"/>
      <geometry>
        <mesh filename="/home/will/Sycobot/rubyrhod_ws/src/vention/meshes/plate_arm.STL"/>
      </geometry>
      <material name="">
        <color rgba="0.33725 0.52941 0.75686 1"/>
      </material>
    </visual>
    <collision>
      <origin rpy="0 0 0" xyz="0 0 0"/>
      <geometry>
        <mesh filename="/home/will/Sycobot/rubyrhod_ws/src/vention/meshes/plate_arm.STL"/>
      </geometry>
    </collision>
  </link>
  <joint name="joint_vention" type="fixed">
    <origin rpy="0 0.00060234 0" xyz="-0.138 0.0093652 0.40569"/>
    <parent link="structure_vention"/>
    <child link="plate_arm"/>
    <axis xyz="0 0 0"/>
  </joint>

  <joint name="mir_fixed" type="fixed">
    <origin rpy="0 0 0" xyz="0 0 0"/>
    <parent link="surface"/>
    <child link="structure_vention"/>
  </joint>
  <joint name="structure_doosan" type="fixed">
    <parent link="plate_arm"/>
    <child link="base_0"/>
    <origin rpy="0 0 0" xyz="0 0 0"/>
  </joint>

  <joint name="doosan_robotiq" type="fixed">
    <parent link="link6"/>
    <child link="robotiq_arg2f_base_link"/>
    <origin rpy="0 0 0" xyz="0 0 0"/>
  </joint>

</robot>

